<?xml version="1.0"?>
<robot name="myfirst">
  <link name="base_link">
    <visual>
      <geometry>
        <mesh filename="package://mantaro_description/meshes/base_link.stl"/>
        <!-- <box size=".27 .39 .17"/> -->
      </geometry>
      <origin rpy="0 0 0" xyz="0 0 0.085"/>
    </visual>
  </link>

  <joint name="base_to_pole" type="fixed">
    <parent link="base_link"/>
    <child link="pole_link"/>
    <origin xyz="0 0 0"/>
  </joint>

  <link name="pole_link">
    <visual>
      <geometry>
	    <mesh filename="package://mantaro_description/meshes/pole.stl"/>
	   <!-- <cylinder length="1.01" radius="0.0125"/> -->
	   </geometry>
	  <origin rpy="0 0 0" xyz="0 0 0"/>
    </visual>
  </link>

  <joint name="pole_to_plate" type="fixed">
    <parent link="pole_link"/>
	<child link="plate_link"/>
	<origin xyz="0 0 0"/>
  </joint>

  <link name="plate_link">
    <visual>
	  <geometry>
	    <mesh filename="package://mantaro_description/meshes/ust.stl"/>
	  </geometry>
	  <origin rpy="0 0 0" xyz="0 0 0"/>
	</visual>
  </link>

  <joint name="plate_to_holder_left" type="fixed">
    <parent link="plate_link"/>
	<child link="holder_link"/>
	<origin xyz="0 0 0"/>
  </joint>

  <joint name="plate_to_holder_right" type="fixed">
    <parent link="plate_link"/>
	<child link="holder_link"/>
	<origin xyz="0 0 0"/>
  </joint>

  <link name="holder_link">
    <visual>
	  <origin rpy="0 0 0" xyz="0 0 0"/>
	</visual>
  </link>

	<!-- wheel.stl sol tekere goredir -->
	 
  <joint name="wheel_left_joint" type="continuous">
    <parent link="base_link"/>
    <child link="wheel_left_link"/>
    <origin rpy="0 0 0" xyz="0.00 0.115 0.0250"/>
    <axis xyz="1 0 0"/>
    <limit effort="100" velocity="100"/>
    <dynamics damping="0.0" friction="0.0"/>
  </joint>
	  
  <link name="wheel_left_link">
    <visual>
	  <geometry>
	    <mesh filename="package://mantaro_description/meshes/wheel.stl"/>
	  </geometry>
    </visual>
    <collision>
      <geometry>
	    <cylinder length="0.0206" radius="0.0352"/>
	  </geometry>
	  <origin rpy="0 0 0" xyz="0 0 0"/>
    </collision>
    <inertial>
	  <mass value="0.01"/>
	  <origin xyz="0 0 0"/>
	  <inertia ixx="0.001" ixy="0.0" ixz="0.0" iyy="0.001" iyz="0.0" izz="0.001"/>
    </inertial>
  </link>
	  
  <joint name="wheel_right_joint" type="continuous">
    <parent link="base_link"/>
    <child link="wheel_right_link"/>
    <origin rpy="0 0 0" xyz="0.16 -0.115 0.0250"/>
    <axis xyz="1 0 0"/>
  </joint>
	  
  <link name="wheel_right_link">
    <visual>
      <geometry>
	    <mesh filename="package://mantaro_description/meshes/wheel.stl"/>
	  </geometry>
    </visual>
    <collision>
      <geometry>
	    <cylinder length="0.0206" radius="0.0350"/>
	  </geometry>
	  <origin rpy="0 0 0" xyz="0 0 0"/>
    </collision>
    <inertial>
	  <mass value="0.01"/>
	  <origin xyz="0 0 0"/>
	  <inertia ixx="0.001" ixy="0.0" ixz="0.0" iyy="0.001" iyz="0.0" izz="0.001"/>
    </inertial>
  </link>
	  
  <joint name="caster_front_joint" type="continuous">
    <parent link="base_link"/>
    <child link="caster_front_link"/>
	<origin rpy="0 0 0" xyz="0.14 0.25 0"/>
	<axis xyz="1 0 0"/>
  </joint>
	  
  <link name="caster_front_link">
    <visual>
	  <geometry>
	    <mesh filename="package://mantaro_description/meshes/wheel.stl"/>
	  </geometry>
    </visual>
	<collision>
	  <geometry>
	    <cylinder length="0.0176" radius="0.017"/>
	  </geometry>
	  <origin rpy="0 0 0" xyz="0 0 0"/>
    </collision>
	<inertial>
	  <mass value="0.01"/>
	  <origin xyz="0 0 0"/>
	  <inertia ixx="0.001" ixy="0.0" ixz="0.0" iyy="0.001" iyz="0.0" izz="0.001"/>
    </inertial>
  </link>
  
</robot>
