<?xml version="1.0"?>
<robot name="mantarobot">
	
  <link name="base_footprint"/>
  
  <joint name="base_joint" type="fixed">
    <origin rpy="0 0 0" xyz="0 0 0"/>
    <parent link="base_footprint"/>
    <child link="base_link"/>
  </joint>
  
  <link name="base_link">
    <visual>
      <geometry>
        <mesh filename="package://mantaro_description/meshes/base.stl"/>
      </geometry>
      <origin rpy="0 0 0" xyz="0 0 0"/>
    </visual>
  </link>

  <joint name="base_to_pole" type="fixed">
    <parent link="base_link"/>
    <child link="pole_link"/>
    <origin xyz="0 0 0.255"/>
  </joint>

  <link name="pole_link">
    <visual>
      <geometry>
	    <mesh filename="package://mantaro_description/meshes/pole.stl"/>
	   </geometry>
	  <origin rpy="0 0 0" xyz="0 0 -0.255"/>
    </visual>
  </link>


<!--
  <joint name="pole_to_plate" type="fixed">
    <parent link="pole_link"/>
	<child link="plate_link"/>
	<origin xyz="0 0 0"/>
  </joint>

  <link name="plate_link">
    <visual>
	  <geometry>
	    <mesh filename="package://mantaro_description/meshes/top_plate.stl"/>
	  </geometry>
	  <origin rpy="0 0 0" xyz="0 0 0"/>
	</visual>
  </link>

  <joint name="plate_to_holder_left" type="fixed">
    <parent link="plate_link"/>
	<child link="holder_link"/>
	<origin xyz="0 0 0"/>
  </joint>

  <joint name="plate_to_holder_right" type="fixed">
    <parent link="plate_link"/>
	<child link="holder_link"/>
	<origin xyz="0 0 0"/>
  </joint>

  <link name="holder_link">
    <visual>
	  <origin rpy="0 0 0" xyz="0 0 0"/>
	</visual>
  </link>
-->
	
	 
  <joint name="wheel_left_joint" type="continuous">
    <parent link="base_link"/>
    <child link="wheel_left_link"/>
    <origin rpy="0 0 0" xyz="0.1210 0.165 0.0551"/>
    <axis xyz="0 1 0"/>
    <limit effort="100" velocity="100"/>
    <dynamics damping="0.0" friction="0.0"/>
  </joint>
	  
  <link name="wheel_left_link">
    <visual>
	  <geometry>
	    <mesh filename="package://mantaro_description/meshes/left_wheel.stl"/>
	  </geometry>
	  <origin rpy="0 0 0" xyz="-0.1210 -0.165 -0.0551"/>
    </visual>
    <collision>
      <geometry>
	    <cylinder length="0.0206" radius="0.0352"/>
	  </geometry>
	  <origin rpy="0 0 0" xyz="0 .285 0"/>
    </collision>
    <inertial>
	  <mass value="0.01"/>
	  <origin xyz="0 0 0"/>
	  <inertia ixx="0.001" ixy="0.0" ixz="0.0" iyy="0.001" iyz="0.0" izz="0.001"/>
    </inertial>
  </link>
	  
  <joint name="wheel_right_joint" type="continuous">
    <parent link="base_link"/>
    <child link="wheel_right_link"/>
    <origin rpy="0 0 0" xyz="0.10925 -0.16 0.0479"/>
    <axis xyz="0 1 0"/>
  </joint>
	  
  <link name="wheel_right_link">
    <visual>
      <geometry>
	    <mesh filename="package://mantaro_description/meshes/right_wheel.stl"/>
	  </geometry>
	  <origin rpy="0 0 0" xyz="-0.10925 0.16 -0.0479"/>
    </visual>
    <collision>
      <geometry>
	    <cylinder length="0.0206" radius="0.0350"/>
	  </geometry>
	  <origin rpy="0 0 0" xyz="0 0 0"/>
    </collision>
    <inertial>
	  <mass value="0.01"/>
	  <origin xyz="0 0 0"/>
	  <inertia ixx="0.001" ixy="0.0" ixz="0.0" iyy="0.001" iyz="0.0" izz="0.001"/>
    </inertial>
  </link>
	  
  <joint name="caster_behind_joint" type="continuous">
    <parent link="base_link"/>
    <child link="caster_behind_link"/>
	<origin rpy="0 0 0" xyz="-0.13 0 0.050"/>
	<axis xyz="0 1 0"/>
  </joint>
	  
  <link name="caster_behind_link">
    <visual>
	  <geometry>
	    <mesh filename="package://mantaro_description/meshes/caster_behind.stl"/>
	  </geometry>
	  <origin rpy="0 0 0" xyz="0.13 0 -0.050"/>
    </visual>
	<collision>
	  <geometry>
	    <cylinder length="0.0176" radius="0.017"/>
	  </geometry>
	  <origin rpy="0 0 0" xyz="0 0 0"/>
    </collision>
	<inertial>
	  <mass value="0.01"/>
	  <origin xyz="0 0 0"/>
	  <inertia ixx="0.001" ixy="0.0" ixz="0.0" iyy="0.001" iyz="0.0" izz="0.001"/>
    </inertial>
  </link> 
  
</robot>
